Workbook
Name \0: #REF!
Name \A: '[1]304-06'!#REF!
Name \B: #REF!
Name \C: #REF!
Name \D: #REF!
Name \E: #REF!
Name \F: #REF!
Name \G: #REF!
Name \H: #REF!
Name \I: #REF!
Name \J: #REF!
Name \K: #REF!
Name \L: #REF!
Name \M: #REF!
Name \N: #REF!
Name \O: #REF!
Name \P: #REF!
Name \q: #REF!
Name \R: #REF!
Name \S: #REF!
Name \T: #REF!
Name \U: #REF!
Name \V: #REF!
Name \W: #REF!
Name \WQ: '[2]BAG-2'!#REF!
Name \x: #REF!
Name \Y: #REF!
Name \Z: #REF!
Name ________MDE06: [3]ALAT!$BO$128
Name ________MDE08: [3]ALAT!$BO$168
Name ________ME06: [3]ALAT!$BO$127
Name ________ME08: [3]ALAT!$BO$167
Name _______MDE06: [3]ALAT!$BO$128
Name _______MDE08: [3]ALAT!$BO$168
Name _______ME06: [3]ALAT!$BO$127
Name _______ME08: [3]ALAT!$BO$167
Name ______MDE06: [3]ALAT!$BO$128
Name ______MDE08: [3]ALAT!$BO$168
Name ______ME06: [3]ALAT!$BO$127
Name ______ME08: [3]ALAT!$BO$167
Name _____bsc100: #REF!
Name _____C94739: [4]ANALISA!#REF!
Name _____DIV1: #REF!
Name _____DIV10: #REF!
Name _____DIV11: #REF!
Name _____DIV2: #REF!
Name _____DIV3: #REF!
Name _____DIV4: #REF!
Name _____DIV5: #REF!
Name _____DIV6: #REF!
Name _____DIV7: #REF!
Name _____DIV8: #REF!
Name _____DIV9: #REF!
Name _____HAL1: #REF!
Name _____HAL2: #REF!
Name _____HAL3: #REF!
Name _____HAL4: #REF!
Name _____HAL5: #REF!
Name _____HAL6: #REF!
Name _____HAL7: #REF!

Sheet RAB 
B8: RENCANA ANGGARAN BIAYA MAINTENANCE & VALIDASI SPARING
B10: Kepada Yth, | H10: Nomor | I10: : | J10: CQC08260429
D11: Bapak Atta | H11: Tanggal | I11: : | J11: 46241
D12: Kawasan Industri Lippo Cikarang | H12: Reff | I12: : | J12: Visit
H13: Pembayaran | I13: : | J13: Fullpayment
B14: Phone. | D14: +62 896-1428-0759 | H14: Validity | I14: : | J14: 30 days
B15: Email | H15: Currency | I15: : | J15: Rupiah
B18: No | C18: Deskripsi
B19: A | C19: Tanpa Pergantian Alat (sensor) | F19: Vol | G19: Sat | H19: Biaya | J19: Total | K19: Diskon
B20: 1. | C20: Jasa Preventive Maintenance (Lingkup Pekerjaan) | F20: 1 | G20: Kunjungan | H20: 5000000 | J20: =F20*H20 -> 5000000 | K20: 0.3
C21: a | D21: Cleaning unit & area
C22: b | D22: Cleaning sensor
C23: c | D23: Pengecekkan & pengukuran power sistem (Panel power, Battery, Inverter, & Solar Panel
C24: d | D24: Pengecekkan status software aplikasi di Datalogger
C25: e | D25: Pengecekkan Hardware Datalogger dan Data Collector
C26: f | D26: Pengecekkan dan pembersihan bak sampling beserta saluran inlet & outlet
C27: g | D27: Pengecekkan status paket data
B29: 2. | C29: Validasi Sensor+CRM ( Teknisi CBI ) | F29: 1 | G29: Kunjungan | H29: 10000000 | J29: =F29*H29 -> 10000000
C30: Pekerjaan kalibrasi dilakukan terhadap Sensor Aquas untuk parameter:
C31: - pH
C32: - Ammonium
C33: dan juga kalibrasi pada Sensor Photonic untuk parameter :
C34: - COD & TSS
C35: Tiap probe yang ada pada sensor tersebut akan dicelupkan ke larutan CRM (Certified Reference Material) standart yang sudah diketahui nilainya, sebagai koreksi dan pengkalibrasi untuk kedua sensor tersebut.
B37: B | C37: Pergantian Alat (Sensor) | F37: Vol | G37: Sat | H37: Biaya | J37: Total
B38: 1. | C38: Penggantian & repair sparepart yang rusak (Corrective Maintenance)
C39: a | D39: Sensor Aquas (pH) | F39: 1 | G39: Pcs | H39: =CBI!G13 -> 15625311 | J39: opsional
C40: b | D40: Sensor Photonic (COD, TSS) | F40: 1 | G40: Pcs | H40: =CBI!G12 -> 1.576167e+08 | J40: opsional
C41: c | D41: Sensor Ammonium | F41: 1 | G41: Pcs | H41: =CBI!G14 -> 104837105 | J41: opsional
C42: d | D42: Sensor Debit | F42: 1 | G42: Pcs | H42: 86750000 | J42: opsional
C43: c | D43: Data Logger | F43: 1 | G43: Pcs | H43: =CBI!G11 -> 33485760 | J43: opsional
C44: d | D44: Mekanik Sparing & Panel Kelistrikan | F44: 1 | G44: Pcs | H44: =CBI!$G$16 -> 46140000 | J44: opsional
C45: e | D45: Cable Sensor | F45: 1 | G45: Pcs | H45: =CBI!$G$17 -> 5250000 | J45: opsional
B47: 2 | C47: Perbaikan data pembacaan dilakukan secara remote
D48: Layanan support perbaikan pembacaan data sparing ( secara remote ) - ( request di luar jam kerja & hari kerja ) | F48: 1 | G48: Kejadian | H48: 350000 | J48: Opsional
D49: Layanan support perbaikan pembacaan data sparing ( secara remote ) - ( request di jam kerja & hari kerja ) | H49: free
C52: Note : Harga yang tertera pada poin B hanya untuk harga pergantian sensor, jika akan melakukan Preventive Maintenance & Kalibrasi maka harus ditambahkan dengan harga pada bagian A poin 1 dan 2
B54: C | C54: Mobilisasi Engineering Cost | F54: Vol | G54: Sat | H54: Biaya | J54: Total
C55: a | D55: Teknisi/Engineering cost | F55: 1 | G55: Kunjungan | H55: 3500000 | J55: =F55*H55 -> 3500000
C56: b | D56: Transportasi darat | F56: 1 | G56: Ls | H56: 1500000 | J56: =F56*H56 -> 1500000
...

Sheet Sheet3
B2: sewa | C2: 400000 | D2: 1 | E2: =D2*C2 -> 400000
B3: bbm | C3: 150000 | D3: 2 | E3: =D3*C3 -> 300000
B4: tol | C4: 150000 | D4: 2 | E4: =D4*C4 -> 300000
E6: =SUM(E2:E4) -> 1000000

Sheet CBI
A2: BOQ PEMBELIAN ALAT SPARING
A5: Lokasi: WWTP Lippo Cikarang Nama PT: PT Lippo Cikarang PURCHASE REQUESTION FORM
A9: NO | B9: NAMA BARANG | C9: MERK / MODEL / TYPE | D9: QTY | E9: SATUAN | F9: ESTIMASI HARGA SATUAN | G9: HARGA | H9: KETERANGAN
A11: 1 | B11: Multiparameter Transmitter | C11: Envilife / Datalogger-01 | D11: 1 | E11: PC | F11: ='[198]Kertas Kertas Sparing'!I4 -> 33485760 | G11: =F11*D11 -> 33485760 | H11: Perangkat Akusisi data sensor ( incl garansi 1 th )
A12: 2 | B12: COD & TSS Sensor | C12: Photonic / MultiProbe/DIP Probe UV254 | D12: 1 | E12: PC | F12: ='[198]Kertas Kertas Sparing'!I5 -> 1.576167e+08 | G12: =F12*D12 -> 1.576167e+08 | H12: Multiprobe: COD & TSS ( Incl masa Garansi 1 th )
A13: 3 | B13: pH Sensor | C13: Aquas /SingleProbe/Max2 | D13: 1 | E13: pc | F13: ='[198]Kertas Kertas Sparing'!I6 -> 15625311 | G13: =F13*D13 -> 15625311 | H13: Single Probe Sensor pH ( Incl masa Garansi 1 th )
A14: 4 | B14: Ammonium | C14: Aquas /SingleProbe/Max2 | D14: 1 | E14: PC | F14: ='[198]Kertas Kertas Sparing'!I7 -> 104837105 | G14: =F14 -> 104837105 | H14: Single Probe Sensor Ammonium ( Incl masa Garansi 1 th )
A15: 5 | B15: TSS, CODeq, pH Sensor, Amonium Assembly | D15: 1 | E15: Set | F15: ='[198]Kertas Kertas Sparing'!I41 -> 43775014 | G15: =F15*D15 -> 43775014 | H15: 1. Instalasi & Testcom 2. Engineering Validasi 3. Kalibrasi KAN
A16: 6 | B16: Mekanik Sparing & Panel Kelistrikan | C16: Envilife | D16: 1 | E16: PC | F16: ='[198]Kertas Kertas Sparing'!I47 -> 46140000 | G16: =F16*D16 -> 46140000 | H16: Material Lokal : Mekanik Sampling Sparing , Panel Kelistrikan & Datalooger
A17: 7 | B17: Cable Sensor | D17: 1 | E17: PC | F17: ='[198]Kertas Kertas Sparing'!I67 -> 5250000 | G17: =F17 -> 5250000 | H17: Kabel Sensor , Kabel Pwr, Lan Kabel, Subduct
A18: 8
A19: 9 | B19: KLHK Connectivity Software and Data Visualization | D19: 1 | E19: PC | F19: 30000000 | G19: =F19*D19 -> 30000000 | H19: Support Konektivitas dengan server KLH dan free Cloud Server selama 1 th
A20: 10 | B20: Project Management, Basic engineering, Design & System Architecture, Documentation | D20: 1 | E20: Set | F20: ='[198]Kertas Kertas Sparing'!I61 -> 21775007 | G20: =F20*D20 -> 21775007 | H20: 1. MCO / Survey 2. Asplan & As Build drawing 3. Project Management ( Dokumen SOP Operasi & Maintenance , Pengiriman dll) 4. Visit Maintenance
A21: 11 | B21: Commissioning of System (Commissioning visit for 3 days) | D21: 1 | E21: Set | G21: =F21*D21 -> 0 | H21: Incl. SoW no 5
A22: 12 | B22: Installation of system | D22: 1 | E22: Set | G22: =F22 -> 0 | H22: Incl. SoW no 5
E23: Total | G23: =SUM(G11:G22) -> 4.585049e+08
